2018-10-01 15:32:51,800 INFO: Microblog startup [in /Users/123seguro/microblog/app/__init__.py:44]
2018-10-01 17:05:41,007 INFO: Microblog startup [in /Users/123seguro/microblog/app/__init__.py:44]
2018-10-01 17:06:58,298 INFO: Microblog startup [in /Users/123seguro/microblog/app/__init__.py:44]
2018-10-01 17:07:18,680 INFO: Microblog startup [in /Users/123seguro/microblog/app/__init__.py:44]
2018-10-03 16:56:48,086 INFO: Microblog startup [in /Users/123seguro/microblog/app/__init__.py:44]
2018-10-03 16:59:10,916 INFO: Microblog startup [in /Users/123seguro/microblog/app/__init__.py:44]
2018-10-03 16:59:18,957 INFO: Microblog startup [in /Users/123seguro/microblog/app/__init__.py:44]
2018-10-03 17:00:09,557 INFO: Microblog startup [in /Users/123seguro/microblog/app/__init__.py:44]
2018-10-03 17:03:16,353 INFO: Microblog startup [in /Users/123seguro/microblog/app/__init__.py:44]
2018-10-03 17:03:20,448 INFO: Microblog startup [in /Users/123seguro/microblog/app/__init__.py:44]
2018-10-04 12:15:14,074 INFO: Microblog startup [in /Users/123seguro/microblog/app/__init__.py:44]
2018-10-04 12:19:50,299 INFO: Microblog startup [in /Users/123seguro/microblog/app/__init__.py:44]
2018-10-04 12:20:33,210 INFO: Microblog startup [in /Users/123seguro/microblog/app/__init__.py:44]
2018-10-04 12:20:38,904 INFO: Microblog startup [in /Users/123seguro/microblog/app/__init__.py:44]
2018-10-04 12:26:53,923 INFO: Microblog startup [in /Users/123seguro/microblog/app/__init__.py:44]
2018-10-04 12:43:00,772 INFO: Microblog startup [in /Users/123seguro/microblog/app/__init__.py:44]
2018-10-04 12:44:49,612 INFO: Microblog startup [in /Users/123seguro/microblog/app/__init__.py:44]
2018-10-04 13:12:12,863 INFO: Microblog startup [in /Users/123seguro/microblog/app/__init__.py:44]
2018-10-04 13:12:21,056 ERROR: Exception on /explore [GET] [in /Users/123seguro/microblog/venv/lib/python3.6/site-packages/flask/app.py:1761]
Traceback (most recent call last):
  File "/Users/123seguro/microblog/venv/lib/python3.6/site-packages/flask/app.py", line 2292, in wsgi_app
    response = self.full_dispatch_request()
  File "/Users/123seguro/microblog/venv/lib/python3.6/site-packages/flask/app.py", line 1815, in full_dispatch_request
    rv = self.handle_user_exception(e)
  File "/Users/123seguro/microblog/venv/lib/python3.6/site-packages/flask/app.py", line 1718, in handle_user_exception
    reraise(exc_type, exc_value, tb)
  File "/Users/123seguro/microblog/venv/lib/python3.6/site-packages/flask/_compat.py", line 35, in reraise
    raise value
  File "/Users/123seguro/microblog/venv/lib/python3.6/site-packages/flask/app.py", line 1813, in full_dispatch_request
    rv = self.dispatch_request()
  File "/Users/123seguro/microblog/venv/lib/python3.6/site-packages/flask/app.py", line 1799, in dispatch_request
    return self.view_functions[rule.endpoint](**req.view_args)
  File "/Users/123seguro/microblog/venv/lib/python3.6/site-packages/flask_login/utils.py", line 261, in decorated_view
    return func(*args, **kwargs)
  File "/Users/123seguro/microblog/app/routes.py", line 139, in explore
    return render_template('index.html', title='Explore', posts=posts)
NameError: name 'posts' is not defined
2018-10-04 13:12:23,884 ERROR: Exception on /explore [GET] [in /Users/123seguro/microblog/venv/lib/python3.6/site-packages/flask/app.py:1761]
Traceback (most recent call last):
  File "/Users/123seguro/microblog/venv/lib/python3.6/site-packages/flask/app.py", line 2292, in wsgi_app
    response = self.full_dispatch_request()
  File "/Users/123seguro/microblog/venv/lib/python3.6/site-packages/flask/app.py", line 1815, in full_dispatch_request
    rv = self.handle_user_exception(e)
  File "/Users/123seguro/microblog/venv/lib/python3.6/site-packages/flask/app.py", line 1718, in handle_user_exception
    reraise(exc_type, exc_value, tb)
  File "/Users/123seguro/microblog/venv/lib/python3.6/site-packages/flask/_compat.py", line 35, in reraise
    raise value
  File "/Users/123seguro/microblog/venv/lib/python3.6/site-packages/flask/app.py", line 1813, in full_dispatch_request
    rv = self.dispatch_request()
  File "/Users/123seguro/microblog/venv/lib/python3.6/site-packages/flask/app.py", line 1799, in dispatch_request
    return self.view_functions[rule.endpoint](**req.view_args)
  File "/Users/123seguro/microblog/venv/lib/python3.6/site-packages/flask_login/utils.py", line 261, in decorated_view
    return func(*args, **kwargs)
  File "/Users/123seguro/microblog/app/routes.py", line 139, in explore
    return render_template('index.html', title='Explore', posts=posts)
NameError: name 'posts' is not defined
2018-10-04 13:14:02,553 INFO: Microblog startup [in /Users/123seguro/microblog/app/__init__.py:44]
2018-10-04 14:59:49,062 INFO: Microblog startup [in /Users/123seguro/microblog/app/__init__.py:44]
2018-10-04 16:40:54,395 INFO: Microblog startup [in /Users/123seguro/microblog/app/__init__.py:44]
2018-10-05 16:25:24,795 INFO: Microblog startup [in /Users/123seguro/microblog/app/__init__.py:46]
2018-10-05 17:33:48,915 INFO: Microblog startup [in /Users/123seguro/microblog/webapp/__init__.py:46]
2018-10-05 17:33:48,915 INFO: Microblog startup [in /Users/123seguro/microblog/webapp/__init__.py:46]
2018-10-12 11:39:49,880 INFO: Microblog startup [in /Users/123seguro/microblog/app/__init__.py:46]
2018-10-12 16:55:35,979 INFO: Microblog startup [in /Users/123seguro/microblog/app/__init__.py:46]
2018-10-12 16:57:55,895 INFO: Microblog startup [in /Users/123seguro/microblog/app/__init__.py:46]
2018-10-12 17:01:19,582 ERROR: Exception on /reset_password_request [POST] [in /Users/123seguro/microblog/venv/lib/python3.6/site-packages/flask/app.py:1761]
Traceback (most recent call last):
  File "/Users/123seguro/microblog/venv/lib/python3.6/site-packages/flask_mail.py", line 492, in send
    message.send(connection)
  File "/Users/123seguro/microblog/venv/lib/python3.6/site-packages/flask_mail.py", line 427, in send
    connection.send(self)
  File "/Users/123seguro/microblog/venv/lib/python3.6/site-packages/flask_mail.py", line 192, in send
    message.rcpt_options)
  File "/Library/Frameworks/Python.framework/Versions/3.6/lib/python3.6/smtplib.py", line 852, in sendmail
    self.ehlo_or_helo_if_needed()
  File "/Library/Frameworks/Python.framework/Versions/3.6/lib/python3.6/smtplib.py", line 600, in ehlo_or_helo_if_needed
    if not (200 <= self.ehlo()[0] <= 299):
  File "/Library/Frameworks/Python.framework/Versions/3.6/lib/python3.6/smtplib.py", line 440, in ehlo
    self.putcmd(self.ehlo_msg, name or self.local_hostname)
  File "/Library/Frameworks/Python.framework/Versions/3.6/lib/python3.6/smtplib.py", line 367, in putcmd
    self.send(str)
  File "/Library/Frameworks/Python.framework/Versions/3.6/lib/python3.6/smtplib.py", line 359, in send
    raise SMTPServerDisconnected('please run connect() first')
smtplib.SMTPServerDisconnected: please run connect() first

During handling of the above exception, another exception occurred:

Traceback (most recent call last):
  File "/Users/123seguro/microblog/venv/lib/python3.6/site-packages/flask/app.py", line 2292, in wsgi_app
    response = self.full_dispatch_request()
  File "/Users/123seguro/microblog/venv/lib/python3.6/site-packages/flask/app.py", line 1815, in full_dispatch_request
    rv = self.handle_user_exception(e)
  File "/Users/123seguro/microblog/venv/lib/python3.6/site-packages/flask/app.py", line 1718, in handle_user_exception
    reraise(exc_type, exc_value, tb)
  File "/Users/123seguro/microblog/venv/lib/python3.6/site-packages/flask/_compat.py", line 35, in reraise
    raise value
  File "/Users/123seguro/microblog/venv/lib/python3.6/site-packages/flask/app.py", line 1813, in full_dispatch_request
    rv = self.dispatch_request()
  File "/Users/123seguro/microblog/venv/lib/python3.6/site-packages/flask/app.py", line 1799, in dispatch_request
    return self.view_functions[rule.endpoint](**req.view_args)
  File "/Users/123seguro/microblog/app/routes.py", line 170, in reset_password_request
    send_password_reset_email(user)
  File "/Users/123seguro/microblog/app/email.py", line 23, in send_password_reset_email
    user=user, token=token))
  File "/Users/123seguro/microblog/app/email.py", line 12, in send_email
    mail.send(msg)
  File "/Users/123seguro/microblog/venv/lib/python3.6/site-packages/flask_mail.py", line 492, in send
    message.send(connection)
  File "/Users/123seguro/microblog/venv/lib/python3.6/site-packages/flask_mail.py", line 152, in __exit__
    self.host.quit()
  File "/Library/Frameworks/Python.framework/Versions/3.6/lib/python3.6/smtplib.py", line 984, in quit
    res = self.docmd("quit")
  File "/Library/Frameworks/Python.framework/Versions/3.6/lib/python3.6/smtplib.py", line 420, in docmd
    self.putcmd(cmd, args)
  File "/Library/Frameworks/Python.framework/Versions/3.6/lib/python3.6/smtplib.py", line 367, in putcmd
    self.send(str)
  File "/Library/Frameworks/Python.framework/Versions/3.6/lib/python3.6/smtplib.py", line 359, in send
    raise SMTPServerDisconnected('please run connect() first')
smtplib.SMTPServerDisconnected: please run connect() first
